<?xml version="1.0" encoding="utf-8"?>
<!-- This URDF was automatically created by SolidWorks to URDF Exporter! Originally created by Stephen Brawner (brawner@gmail.com) 
     Commit Version: 1.6.0-1-g15f4949  Build Version: 1.6.7594.29634
     For more information, please see http://wiki.ros.org/sw_urdf_exporter -->
<robot
  name="MINI_CAD">
  <link
    name="Body">
    <inertial>
      <origin
        xyz="-0.00919575896316816 -0.00047172605195048 -0.0160791655999242"
        rpy="0 0 0" />
      <mass
        value="0.243719079270464" />
      <inertia
        ixx="9.53655975027727E-05"
        ixy="-3.64239711648365E-08"
        ixz="-9.1103377066178E-06"
        iyy="6.68555733239033E-05"
        iyz="7.46924365468656E-07"
        izz="9.51842607920804E-05" />
    </inertial>
    <visual>
      <origin
        xyz="0 0 0"
        rpy="0 0 0" />
      <geometry>
        <mesh
          filename="package://MINI_CAD/meshes/Body.STL" />
      </geometry>
      <material
        name="">
        <color
          rgba="0.752941176470588 0.752941176470588 0.752941176470588 1" />
      </material>
    </visual>
    <collision>
      <origin
        xyz="0 0 0"
        rpy="0 0 0" />
      <geometry>
        <mesh
          filename="package://MINI_CAD/meshes/Body.STL" />
      </geometry>
    </collision>
  </link>
  <link
    name="L_arm_01">
    <inertial>
      <origin
        xyz="-1.41270208100188E-09 0.00456865100998909 0.00915593369616431"
        rpy="0 0 0" />
      <mass
        value="0.0042561997534061" />
      <inertia
        ixx="4.75526787509678E-07"
        ixy="-5.17770412701755E-14"
        ixz="-2.75755878362634E-14"
        iyy="1.1065023720425E-06"
        iyz="-1.26621947092053E-07"
        izz="1.10384151673518E-06" />
    </inertial>
    <visual>
      <origin
        xyz="0 0 0"
        rpy="0 0 0" />
      <geometry>
        <mesh
          filename="package://MINI_CAD/meshes/L_arm_01.STL" />
      </geometry>
      <material
        name="">
        <color
          rgba="0.752941176470588 0.752941176470588 0.752941176470588 1" />
      </material>
    </visual>
    <collision>
      <origin
        xyz="0 0 0"
        rpy="0 0 0" />
      <geometry>
        <mesh
          filename="package://MINI_CAD/meshes/L_arm_01.STL" />
      </geometry>
    </collision>
  </link>
  <joint
    name="Joint_02"
    type="continuous">
    <origin
      xyz="0 0 0.0389984717412249"
      rpy="0 0 0" />
    <parent
      link="Body" />
    <child
      link="L_arm_01" />
    <axis
      xyz="0 0 1" />
  </joint>
  <link
    name="L_arm_02">
    <inertial>
      <origin
        xyz="5.46978612398646E-05 0.0120458330772935 0.000970490232161886"
        rpy="0 0 0" />
      <mass
        value="0.0230012005288788" />
      <inertia
        ixx="3.19855855058084E-06"
        ixy="6.229448689716E-08"
        ixz="2.12827267593057E-13"
        iyy="2.79006394276286E-06"
        iyz="2.84312896323333E-07"
        izz="4.15271742011241E-06" />
    </inertial>
    <visual>
      <origin
        xyz="0 0 0"
        rpy="0 0 0" />
      <geometry>
        <mesh
          filename="package://MINI_CAD/meshes/L_arm_02.STL" />
      </geometry>
      <material
        name="">
        <color
          rgba="0.752941176470588 0.752941176470588 0.752941176470588 1" />
      </material>
    </visual>
    <collision>
      <origin
        xyz="0 0 0"
        rpy="0 0 0" />
      <geometry>
        <mesh
          filename="package://MINI_CAD/meshes/L_arm_02.STL" />
      </geometry>
    </collision>
  </link>
  <joint
    name="Joint_04"
    type="continuous">
    <origin
      xyz="0 0.012 0.0180015282587751"
      rpy="1.5707963267949 0 0" />
    <parent
      link="L_arm_01" />
    <child
      link="L_arm_02" />
    <axis
      xyz="1 0 0" />
  </joint>
  <link
    name="L_arm_03">
    <inertial>
      <origin
        xyz="-0.000178609255192013 0.0199985926013709 0.00128706351286216"
        rpy="0 0 0" />
      <mass
        value="0.026158162956425" />
      <inertia
        ixx="2.36571031389844E-06"
        ixy="5.56452220588877E-08"
        ixz="2.36320882682133E-13"
        iyy="1.96473201193679E-06"
        iyz="1.32983545780728E-08"
        izz="2.73594377881704E-06" />
    </inertial>
    <visual>
      <origin
        xyz="0 0 0"
        rpy="0 0 0" />
      <geometry>
        <mesh
          filename="package://MINI_CAD/meshes/L_arm_03.STL" />
      </geometry>
      <material
        name="">
        <color
          rgba="0.752941176470588 0.752941176470588 0.752941176470588 1" />
      </material>
    </visual>
    <collision>
      <origin
        xyz="0 0 0"
        rpy="0 0 0" />
      <geometry>
        <mesh
          filename="package://MINI_CAD/meshes/L_arm_03.STL" />
      </geometry>
    </collision>
  </link>
  <joint
    name="Joint_06"
    type="continuous">
    <origin
      xyz="0 0.045 0"
      rpy="0 0 0" />
    <parent
      link="L_arm_02" />
    <child
      link="L_arm_03" />
    <axis
      xyz="1 0 0" />
  </joint>
  <link
    name="R_arm_01">
    <inertial>
      <origin
        xyz="-1.41270282793737E-09 0.00456865100998955 0.00915593369616418"
        rpy="0 0 0" />
      <mass
        value="0.0042561997534057" />
      <inertia
        ixx="4.75526787509663E-07"
        ixy="-5.17770577637113E-14"
        ixz="-2.75755836839386E-14"
        iyy="1.10650237204247E-06"
        iyz="-1.26621947092055E-07"
        izz="1.10384151673514E-06" />
    </inertial>
    <visual>
      <origin
        xyz="0 0 0"
        rpy="0 0 0" />
      <geometry>
        <mesh
          filename="package://MINI_CAD/meshes/R_arm_01.STL" />
      </geometry>
      <material
        name="">
        <color
          rgba="0.752941176470588 0.752941176470588 0.752941176470588 1" />
      </material>
    </visual>
    <collision>
      <origin
        xyz="0 0 0"
        rpy="0 0 0" />
      <geometry>
        <mesh
          filename="package://MINI_CAD/meshes/R_arm_01.STL" />
      </geometry>
    </collision>
  </link>
  <joint
    name="Joint_01"
    type="continuous">
    <origin
      xyz="0 0 -0.038998471741225"
      rpy="-3.14159265358979 0 -3.14159265358979" />
    <parent
      link="Body" />
    <child
      link="R_arm_01" />
    <axis
      xyz="0 0 1" />
  </joint>
  <link
    name="R_arm_02">
    <inertial>
      <origin
        xyz="-5.46980825606699E-05 0.0120458330772934 0.00097049234653049"
        rpy="0 0 0" />
      <mass
        value="0.0230012005288787" />
      <inertia
        ixx="3.19855855058083E-06"
        ixy="-6.22945892654359E-08"
        ixz="2.12827266521488E-13"
        iyy="2.79006394276285E-06"
        iyz="2.84313451256825E-07"
        izz="4.1527174201124E-06" />
    </inertial>
    <visual>
      <origin
        xyz="0 0 0"
        rpy="0 0 0" />
      <geometry>
        <mesh
          filename="package://MINI_CAD/meshes/R_arm_02.STL" />
      </geometry>
      <material
        name="">
        <color
          rgba="0.752941176470588 0.752941176470588 0.752941176470588 1" />
      </material>
    </visual>
    <collision>
      <origin
        xyz="0 0 0"
        rpy="0 0 0" />
      <geometry>
        <mesh
          filename="package://MINI_CAD/meshes/R_arm_02.STL" />
      </geometry>
    </collision>
  </link>
  <joint
    name="Joint_03"
    type="continuous">
    <origin
      xyz="0 0.012 0.0180015282587751"
      rpy="1.5707963267949 0 0" />
    <parent
      link="R_arm_01" />
    <child
      link="R_arm_02" />
    <axis
      xyz="1 0 0" />
  </joint>
  <link
    name="R_arm_03">
    <inertial>
      <origin
        xyz="0.000178609255192039 0.0199985926013709 0.0012870653720527"
        rpy="0 0 0" />
      <mass
        value="0.0261581629564249" />
      <inertia
        ixx="2.36571031389844E-06"
        ixy="-5.5645222058886E-08"
        ixz="2.36320882970304E-13"
        iyy="1.96473201193679E-06"
        iyz="1.32989095115652E-08"
        izz="2.73594377881704E-06" />
    </inertial>
    <visual>
      <origin
        xyz="0 0 0"
        rpy="0 0 0" />
      <geometry>
        <mesh
          filename="package://MINI_CAD/meshes/R_arm_03.STL" />
      </geometry>
      <material
        name="">
        <color
          rgba="0.752941176470588 0.752941176470588 0.752941176470588 1" />
      </material>
    </visual>
    <collision>
      <origin
        xyz="0 0 0"
        rpy="0 0 0" />
      <geometry>
        <mesh
          filename="package://MINI_CAD/meshes/R_arm_03.STL" />
      </geometry>
    </collision>
  </link>
  <joint
    name="Joint_05"
    type="continuous">
    <origin
      xyz="0 0.0449999999999995 0"
      rpy="0 0 0" />
    <parent
      link="R_arm_02" />
    <child
      link="R_arm_03" />
    <axis
      xyz="1 0 0" />
  </joint>
  <link
    name="L_leg_01">
    <inertial>
      <origin
        xyz="-0.00122067250704312 -0.00016509160146036 0.0135307278454896"
        rpy="0 0 0" />
      <mass
        value="0.0199023992993581" />
      <inertia
        ixx="1.60303747954796E-06"
        ixy="6.22927670873075E-08"
        ixz="4.68736294907936E-10"
        iyy="2.15853088455321E-06"
        iyz="-2.33572917558891E-09"
        izz="2.46876806019735E-06" />
    </inertial>
    <visual>
      <origin
        xyz="0 0 0"
        rpy="0 0 0" />
      <geometry>
        <mesh
          filename="package://MINI_CAD/meshes/L_leg_01.STL" />
      </geometry>
      <material
        name="">
        <color
          rgba="0.752941176470588 0.752941176470588 0.752941176470588 1" />
      </material>
    </visual>
    <collision>
      <origin
        xyz="0 0 0"
        rpy="0 0 0" />
      <geometry>
        <mesh
          filename="package://MINI_CAD/meshes/L_leg_01.STL" />
      </geometry>
    </collision>
  </link>
  <joint
    name="Joint_8"
    type="continuous">
    <origin
      xyz="0 0.0720000000000003 0.0239999999999996"
      rpy="1.56326728402668 0 1.57079632679526" />
    <parent
      link="Body" />
    <child
      link="L_leg_01" />
    <axis
      xyz="0 0.00752897163592653 -0.999971656891387" />
  </joint>
  <link
    name="L_leg_02">
    <inertial>
      <origin
        xyz="-0.000970492346530153 -0.0329541669227065 -5.46980825606724E-05"
        rpy="0 0 0" />
      <mass
        value="0.0230012005288788" />
      <inertia
        ixx="4.1527174201124E-06"
        ixy="-2.84313451256824E-07"
        ixz="-2.12827266440283E-13"
        iyy="2.79006394276285E-06"
        iyz="-6.22945892654347E-08"
        izz="3.19855855058084E-06" />
    </inertial>
    <visual>
      <origin
        xyz="0 0 0"
        rpy="0 0 0" />
      <geometry>
        <mesh
          filename="package://MINI_CAD/meshes/L_leg_02.STL" />
      </geometry>
      <material
        name="">
        <color
          rgba="0.752941176470588 0.752941176470588 0.752941176470588 1" />
      </material>
    </visual>
    <collision>
      <origin
        xyz="0 0 0"
        rpy="0 0 0" />
      <geometry>
        <mesh
          filename="package://MINI_CAD/meshes/L_leg_02.STL" />
      </geometry>
    </collision>
  </link>
  <joint
    name="Joint_10"
    type="continuous">
    <origin
      xyz="0.00599999999999463 -0.000112934493935884 0.0149995748539799"
      rpy="0 1.56326728402669 1.57079632674711" />
    <parent
      link="L_leg_01" />
    <child
      link="L_leg_02" />
    <axis
      xyz="0 0 1" />
  </joint>
  <link
    name="L_leg_03">
    <inertial>
      <origin
        xyz="0.0178997451661013 5.26347186322051E-09 0.00688303209754276"
        rpy="0 0 0" />
      <mass
        value="0.00898936103979377" />
      <inertia
        ixx="2.9704404119114E-06"
        ixy="-3.98245145228418E-13"
        ixz="4.51182757180571E-07"
        iyy="3.47626399724056E-06"
        iyz="-2.83187827957451E-13"
        izz="4.72558607476269E-06" />
    </inertial>
    <visual>
      <origin
        xyz="0 0 0"
        rpy="0 0 0" />
      <geometry>
        <mesh
          filename="package://MINI_CAD/meshes/L_leg_03.STL" />
      </geometry>
      <material
        name="">
        <color
          rgba="0.752941176470588 0.752941176470588 0.752941176470588 1" />
      </material>
    </visual>
    <collision>
      <origin
        xyz="0 0 0"
        rpy="0 0 0" />
      <geometry>
        <mesh
          filename="package://MINI_CAD/meshes/L_leg_03.STL" />
      </geometry>
    </collision>
  </link>
  <joint
    name="Joint_12"
    type="continuous">
    <origin
      xyz="0 -0.045 0"
      rpy="1.5707963267949 0 -1.5707963267949" />
    <parent
      link="L_leg_02" />
    <child
      link="L_leg_03" />
    <axis
      xyz="0 1 0" />
  </joint>
  <link
    name="L_leg_04">
    <inertial>
      <origin
        xyz="-0.00622990861915074 -6.42923681114342E-05 -0.00175974324020421"
        rpy="0 0 0" />
      <mass
        value="0.0195687148748515" />
      <inertia
        ixx="1.57200312090151E-06"
        ixy="6.22945380812975E-08"
        ixz="-2.77466745478215E-13"
        iyy="2.25015128902117E-06"
        iyz="2.36320882360163E-13"
        izz="2.57130700251407E-06" />
    </inertial>
    <visual>
      <origin
        xyz="0 0 0"
        rpy="0 0 0" />
      <geometry>
        <mesh
          filename="package://MINI_CAD/meshes/L_leg_04.STL" />
      </geometry>
      <material
        name="">
        <color
          rgba="0.752941176470588 0.752941176470588 0.752941176470588 1" />
      </material>
    </visual>
    <collision>
      <origin
        xyz="0 0 0"
        rpy="0 0 0" />
      <geometry>
        <mesh
          filename="package://MINI_CAD/meshes/L_leg_04.STL" />
      </geometry>
    </collision>
  </link>
  <joint
    name="Joint_14"
    type="continuous">
    <origin
      xyz="0.0419999999999999 0 0"
      rpy="0 0 0" />
    <parent
      link="L_leg_03" />
    <child
      link="L_leg_04" />
    <axis
      xyz="0 1 0" />
  </joint>
  <link
    name="L_leg_05">
    <inertial>
      <origin
        xyz="0.012247622803089 0.00770948764935718 -0.0211727728731079"
        rpy="0 0 0" />
      <mass
        value="0.0365288623421764" />
      <inertia
        ixx="2.06601022343598E-05"
        ixy="-2.16309062241244E-08"
        ixz="-1.5264809467841E-06"
        iyy="1.66432233486565E-05"
        iyz="-7.61437903491916E-08"
        izz="6.87393581331487E-06" />
    </inertial>
    <visual>
      <origin
        xyz="0 0 0"
        rpy="0 0 0" />
      <geometry>
        <mesh
          filename="package://MINI_CAD/meshes/L_leg_05.STL" />
      </geometry>
      <material
        name="">
        <color
          rgba="0.752941176470588 0.752941176470588 0.752941176470588 1" />
      </material>
    </visual>
    <collision>
      <origin
        xyz="0 0 0"
        rpy="0 0 0" />
      <geometry>
        <mesh
          filename="package://MINI_CAD/meshes/L_leg_05.STL" />
      </geometry>
    </collision>
  </link>
  <joint
    name="Joint_16"
    type="continuous">
    <origin
      xyz="0 0 0"
      rpy="0.014169501922711 0 0" />
    <parent
      link="L_leg_04" />
    <child
      link="L_leg_05" />
    <axis
      xyz="0 0.0141690277810197 0.999899614287225" />
  </joint>
  <link
    name="R_leg_01">
    <inertial>
      <origin
        xyz="-0.0012206725078875 6.32144396902727E-05 0.0135315848690105"
        rpy="0 0 0" />
      <mass
        value="0.0199023992993582" />
      <inertia
        ixx="1.60303748122172E-06"
        ixy="-6.22945380812976E-08"
        ixz="2.77466746796284E-13"
        iyy="2.15851329852161E-06"
        iyz="2.3632088250148E-13"
        izz="2.4687856445552E-06" />
    </inertial>
    <visual>
      <origin
        xyz="0 0 0"
        rpy="0 0 0" />
      <geometry>
        <mesh
          filename="package://MINI_CAD/meshes/R_leg_01.STL" />
      </geometry>
      <material
        name="">
        <color
          rgba="0.752941176470588 0.752941176470588 0.752941176470588 1" />
      </material>
    </visual>
    <collision>
      <origin
        xyz="0 0 0"
        rpy="0 0 0" />
      <geometry>
        <mesh
          filename="package://MINI_CAD/meshes/R_leg_01.STL" />
      </geometry>
    </collision>
  </link>
  <joint
    name="Joint_07"
    type="continuous">
    <origin
      xyz="0 0.0720000000000001 -0.0239999999999999"
      rpy="1.5707963267949 0 1.5707963267949" />
    <parent
      link="Body" />
    <child
      link="R_leg_01" />
    <axis
      xyz="0 0 1" />
  </joint>
  <link
    name="R_Leg_02">
    <inertial>
      <origin
        xyz="-0.000970492346530157 -0.0329541669227065 -5.46980825606759E-05"
        rpy="0 0 0" />
      <mass
        value="0.0230012005288788" />
      <inertia
        ixx="4.1527174201124E-06"
        ixy="-2.84313451256824E-07"
        ixz="-2.12827266455308E-13"
        iyy="2.79006394276285E-06"
        iyz="-6.22945892654347E-08"
        izz="3.19855855058084E-06" />
    </inertial>
    <visual>
      <origin
        xyz="0 0 0"
        rpy="0 0 0" />
      <geometry>
        <mesh
          filename="package://MINI_CAD/meshes/R_Leg_02.STL" />
      </geometry>
      <material
        name="">
        <color
          rgba="0.752941176470588 0.752941176470588 0.752941176470588 1" />
      </material>
    </visual>
    <collision>
      <origin
        xyz="0 0 0"
        rpy="0 0 0" />
      <geometry>
        <mesh
          filename="package://MINI_CAD/meshes/R_Leg_02.STL" />
      </geometry>
    </collision>
  </link>
  <joint
    name="Joint_09"
    type="fixed">
    <origin
      xyz="0.00600000000000023 0.0479999999999995 0.015"
      rpy="1.5707963267949 1.5707963267949 0" />
    <parent
      link="R_leg_01" />
    <child
      link="R_Leg_02" />
    <axis
      xyz="0 0 0" />
  </joint>
  <link
    name="R_leg_03">
    <inertial>
      <origin
        xyz="0.062899745166101 -0.0180000980420397 0.00688303209754421"
        rpy="0 0 0" />
      <mass
        value="0.00898936103979292" />
      <inertia
        ixx="2.97044041191102E-06"
        ixy="-3.9180621070142E-13"
        ixz="4.51182757180514E-07"
        iyy="3.47626399724035E-06"
        iyz="-2.88931235574408E-13"
        izz="4.72558607476253E-06" />
    </inertial>
    <visual>
      <origin
        xyz="0 0 0"
        rpy="0 0 0" />
      <geometry>
        <mesh
          filename="package://MINI_CAD/meshes/R_leg_03.STL" />
      </geometry>
      <material
        name="">
        <color
          rgba="0.752941176470588 0.752941176470588 0.752941176470588 1" />
      </material>
    </visual>
    <collision>
      <origin
        xyz="0 0 0"
        rpy="0 0 0" />
      <geometry>
        <mesh
          filename="package://MINI_CAD/meshes/R_leg_03.STL" />
      </geometry>
    </collision>
  </link>
  <joint
    name="Joint_11"
    type="continuous">
    <origin
      xyz="0 0 -0.0299998969223451"
      rpy="1.5707963267949 0 -1.5707963267949" />
    <parent
      link="R_Leg_02" />
    <child
      link="R_leg_03" />
    <axis
      xyz="0 1 0" />
  </joint>
  <link
    name="R_leg_04">
    <inertial>
      <origin
        xyz="-0.00622990861915076 -0.0149357076318887 -0.00175974572544711"
        rpy="0 0 0" />
      <mass
        value="0.0195687148748515" />
      <inertia
        ixx="1.57200312090151E-06"
        ixy="-6.22945380812994E-08"
        ixz="2.77466746832561E-13"
        iyy="2.25015128902117E-06"
        iyz="2.36320883095189E-13"
        izz="2.57130700251407E-06" />
    </inertial>
    <visual>
      <origin
        xyz="0 0 0"
        rpy="0 0 0" />
      <geometry>
        <mesh
          filename="package://MINI_CAD/meshes/R_leg_04.STL" />
      </geometry>
      <material
        name="">
        <color
          rgba="0.752941176470588 0.752941176470588 0.752941176470588 1" />
      </material>
    </visual>
    <collision>
      <origin
        xyz="0 0 0"
        rpy="0 0 0" />
      <geometry>
        <mesh
          filename="package://MINI_CAD/meshes/R_leg_04.STL" />
      </geometry>
    </collision>
  </link>
  <joint
    name="Joint_13"
    type="continuous">
    <origin
      xyz="0.087 -0.00300010307765432 0"
      rpy="0 0 0" />
    <parent
      link="R_leg_03" />
    <child
      link="R_leg_04" />
    <axis
      xyz="0 1 0" />
  </joint>
  <link
    name="R_leg_05">
    <inertial>
      <origin
        xyz="0.0122476213713946 -0.00600871393403258 -0.0210614114822717"
        rpy="0 0 0" />
      <mass
        value="0.0365288623421758" />
      <inertia
        ixx="2.06601022349224E-05"
        ixy="6.84109501190224E-14"
        ixz="-1.52663372444367E-06"
        iyy="1.66434196036713E-05"
        iyz="-6.22949019507235E-08"
        izz="6.87373955773587E-06" />
    </inertial>
    <visual>
      <origin
        xyz="0 0 0"
        rpy="0 0 0" />
      <geometry>
        <mesh
          filename="package://MINI_CAD/meshes/R_leg_05.STL" />
      </geometry>
      <material
        name="">
        <color
          rgba="0.752941176470588 0.752941176470588 0.752941176470588 1" />
      </material>
    </visual>
    <collision>
      <origin
        xyz="0 0 0"
        rpy="0 0 0" />
      <geometry>
        <mesh
          filename="package://MINI_CAD/meshes/R_leg_05.STL" />
      </geometry>
    </collision>
  </link>
  <joint
    name="Joint_15"
    type="continuous">
    <origin
      xyz="0 -0.0170000000000006 0"
      rpy="0 0 0" />
    <parent
      link="R_leg_04" />
    <child
      link="R_leg_05" />
    <axis
      xyz="0 0 1" />
  </joint>
</robot>